Workbook

Sheet README
A1: OT Historian — Asset Metadata Model
A2: Single source of truth for Line → Machine → Station → Parameter hierarchy
A4: STRUCTURE (normalized — four linked tables):
A5: Lines one row per production line
A6: Machines one row per machine (LineID links to Lines)
A7: Stations one row per station (MachineID links to Machines)
A8: Parameters one row per tag/sensor (StationID links to Stations)
A10: COLOUR KEY:
A11: Orange cell = Primary Key (the ID for that table — keep unique)
A12: Blue cell = Foreign Key (must match an ID in the parent table)
A13: Green cell = Calculated (do not type over — it is a formula)
A15: HOW TO USE:
... A25: • Sample rows are illustrative — replace with your real assets.

Sheet Lines
A1: LineID | B1: LineName | C1: Site | D1: Area | E1: Description | F1: OEM_Manufacturer | G1: Install_Date | H1: Maintenance_Window | I1: Status | J1: SME | K1: Controls | L1: Legeacy Data Analytics Solutions
A2: NGP2 | B2: NGP2 Packaging Line 1 | C2: Ballina | D2: Continence | E2: High-speed packaging line | F2: Bosch Rexroth | G2: 2021-03-15 | H2: CMMS TBC | I2: Active
A3: HU3 | B3: HU3 Assembly Line | C3: Ballina | D3: Ostomy | E3: Primary assembly line | F3: Siemens | G3: 2020-09-01 | H3: CMMS TBC | I3: Active
A4: P17 | B4: Kaunas P17 Line | C4: Kaunas | D4: Ostomy | E4: Forming and pouching line | F4: Krones | G4: 2022-06-10 | H4: CMMS TBC | I4: Active
A5: VCL6 | B5: Ballina VCL6 Line | C5: Ballina | D5: Continence | E5: Catheter coating machine | F5: B&R | G5: 2019-11-20 | H5: CMMS TBC | I5: Active
A6: BFX | C6: Ballina | D6: Ostomy | I6: Active | J6: Stephen Gallagher | K6: Damien Kelly, Padraig O'Malley, Moiz Rehman
A7: BIM 03 | C7: Ballina | D7: Ostomy | I7: Active | J7: Stephen Gallagher | K7: Damien Kelly, Padraig O'Malley, Moiz Rehman
A8: BIM 08 | C8: Ballina | D8: Ostomy | I8: Active | J8: Stephen Gallagher | K8: Damien Kelly, Padraig O'Malley, Moiz Rehman
A9: BIM 12 | C9: Ballina | D9: Ostomy | I9: Active | J9: Stephen Gallagher | K9: Damien Kelly, Padraig O'Malley, Moiz Rehman
A10: HU2 | C10: Ballina | D10: Ostomy | I10: Active | J10: Roy Sheridan | K10: Damien Kelly, Padraig O'Malley, Moiz Rehman
A11: HU3 | C11: Ballina | D11: Ostomy | I11: Active | J11: Roy Sheridan | K11: Damien Kelly, Padraig O'Malley, Moiz Rehman
A12: Extruder 2 | C12: Ballina | D12: Ostomy | I12: Active | J12: Conor Toughey | K12: Damien Kelly, Padraig O'Malley, Moiz Rehman
A13: Extruder 3 | C13: Ballina | D13: Ostomy | I13: Active | J13: Conor Toughey | K13: Damien Kelly, Padraig O'Malley, Moiz Rehman
A14: 1AC3 | B14: 1AC3 Auto Coiner | C14: Ballina | D14: Ostomy | E14: Barrier applicator cell (bag & insert/drumhead recipes) | F14: Unknown | G14: Manual version markings only: GMI-00044 v1.0 (1PC Auto Coiner - bag/pouch recipe) and GMI-00006 v12.0 (Autocoiner - general/insert-drumhead recipe); no equipment install date stated. | I14: Active | J14: Ollie Lynn | K14: Damien Kelly, Padraig O'Malley, Moiz Rehman
A15: 1AC4 | C15: Ballina | D15: Ostomy | I15: Active | J15: Ollie Lynn | K15: Damien Kelly, Padraig O'Malley, Moiz Rehman
A16: 1AC5 | C16: Ballina | D16: Ostomy | I16: Active | J16: Ollie Lynn | K16: Damien Kelly, Padraig O'Malley, Moiz Rehman
A17: 1AC6 | C17: Ballina | D17: Ostomy | I17: Active | J17: Ollie Lynn | K17: Damien Kelly, Padraig O'Malley, Moiz Rehman
A18: 1AC7 | C18: Ballina | D18: Ostomy | I18: Active | J18: Ollie Lynn | K18: Damien Kelly, Padraig O'Malley, Moiz Rehman
A19: 1AC8 | C19: Ballina | D19: Ostomy | I19: Active | J19: Ollie Lynn | K19: Damien Kelly, Padraig O'Malley, Moiz Rehman
A20: K2 | C20: Ballina | D20: Ostomy | I20: Active | J20: Micheal Reilly | K20: Damien Kelly, Padraig O'Malley, Moiz Rehman
A21: K3 | C21: Ballina | D21: Ostomy | I21: Active | J21: Liam Morris | K21: Damien Kelly, Padraig O'Malley, Moiz Rehman
A22: K9 | B22: K9 | C22: Ballina | D22: Ostomy | E22: Inline ostomy-bag forming, welding & punching cell | F22: KIEFEL GmbH (a member of the Brückner Group), Germany | G22: Manual drawn up 06/10 (June 2010), Rev.: 0 | I22: Active | J22: Colin Tempany | K22: Damien Kelly, Padraig O'Malley, Moiz Rehman
A23: HOS4 | C23: Ballina | D23: Ostomy | I23: Active | J23: Derick Tansey | K23: Damien Kelly, Padraig O'Malley, Moiz Rehman
A24: PS1 | C24: Ballina | D24: Continence | I24: Active | J24: Ben Gallagher | K24: Declan Roarty
A25: PS2 | C25: Ballina | D25: Continence | I25: Active | J25: Ben Gallagher | K25: Declan Roarty
A26: PS3 | C26: Ballina | D26: Continence | I26: Active | J26: Ben Gallagher | K26: Declan Roarty
A27: PS4 | C27: Ballina | D27: Continence | I27: Active | J27: Noel Gilroy (GE) | K27: Declan Roarty
A28: PS5 | C28: Ballina | D28: Continence | I28: Active | J28: Ben Gallagher | K28: Declan Roarty
A29: PS6 | C29: Ballina | D29: Continence | I29: Active | J29: Ben Gallagher | K29: Declan Roarty
A30: PS7 | C30: Ballina | D30: Continence | I30: Active | J30: Ben Gallagher | K30: Declan Roarty
A31: PS8 | C31: Ballina | D31: Continence | I31: Active | J31: Ben Gallagher | K31: Declan Roarty
A32: HOS3 | C32: Ballina | D32: Continence | I32: Active | J32: Ben Gallagher
A33: CSA2 | C33: Ballina | D33: Continence | I33: Active | J33: Ian Morris | K33: Tony Murray
A34: CSA3 | C34: Ballina | D34: Continence | I34: Active | J34: Ian Morris | K34: Tony Murray
A35: ICX 2 | C35: Ballina | D35: Continence | I35: Active | J35: Paul Roughneen
A36: VCL4 | C36: Ballina | D36: Continence | I36: Active | J36: Ian Morris
A37: VCL5 | C37: Ballina | D37: Continence | I37: Active | J37: Tony Murray | K37: Tony Murray
A38: VCL6 | C38: Ballina | D38: Continence | I38: Active | J38: Ian Morris/Paul Roughneen | K38: Declan Roarty
A39: Ulma 2 | C39: Ballina | D39: Continence | I39: Active | J39: Peter Mortimer/ David Egan | K39: Cathal Gorman
A40: CPM4 | C40: Ballina | D40: Continence | I40: Active | J40: Peter Mortimer/ David Egan
...

Sheet Machines
A1: MachineID | B1: MachineName | C1: LineID | D1: Equipment_Type | E1: Serial_Number | F1: Position_In_Line | G1: OEM_Contact | H1: PLC_Make | I1: PLC_Credentials_Status | J1: Status
A2: MC002 | B2: Auto Coiner | C2: 1AC3 | D2: Barrier Forming, Preheat, Punch, Print, Glue & Seal Machine (bag/pouch and insert/drumhead recipes) | E2: Unknown | F2: 1 | G2: Unknown | H2: Unknown | I2: true | J2: Active
A3: MC003 | B3: HF 11 | C3: HF11 | D3: Automated Web-Fed Pouch Forming, Sealing & Punching Line | E3: Unknown | F3: 1 | G3: Unknown | H3: Unknown | I3: true | J3: Active
A4: MC004 | B4: Inline System KIT 70/20 | C4: K9 | D4: Integrated Inline Production/Assembly System (Ostomy Bag Manufacturing Cell) | E4: 413-040 - B 921 | F4: 1 | G4: Unknown | H4: Siemens (IPC477C Pro with MP Touch operator panel) | I4: true | J4: Active
A5: MC005 | B5: Inline System KIT 70/20 | C5: K10 | D5: Integrated Inline Production/Assembly System (Ostomy Bag Manufacturing Cell) | E5: Unknown (K10-specific serial not in shared manual) | F5: 1 | G5: Unknown | H5: Siemens (IPC477C Pro with MP Touch operator panel) | I5: true | J5: Active
A6: MC006 | B6: Inline System KIT 70/20 | C6: K13 | D6: Integrated Inline Production/Assembly System (Ostomy Bag Manufacturing Cell) | E6: 413-052 - C377 (unverified - assigned by list order, see notes) | F6: 1 | G6: Unknown | H6: Siemens (WinCC flexible HMI - per this line's own tag export header; not explicitly stated in this manual's own text) | I6: true | J6: Active
A7: MC007 | B7: Inline System KIT 70/20 | C7: K14 | D7: Integrated Inline Production/Assembly System (Ostomy Bag Manufacturing Cell) | E7: Unknown | F7: 1 | G7: Unknown | H7: Siemens (WinCC flexible HMI - per this line's own tag export header; not explicitly stated in the shared K11-13 manual's own text) | I7: true | J7: Active

Sheet Stations
A1: StationID | B1: StationName | C1: MachineID | D1: Station_Type | E1: ISA95_Level | F1: Status
A2: MC002-BarrierInfeedSystem | B2: Barrier Infeed System | C2: MC002 | D2: Magazine | E2: L2 | F2: Active
A3: MC002-BarrierLoadStation | B3: Barrier Load Station | C3: MC002 | D3: Robot/Pick-and-Place | E3: L2 | F3: Active
A4: MC002-CoronaTreatment | B4: Corona Treatment | C4: MC002 | D4: Surface Treatment | E4: L2 | F4: Active
A5: MC002-MainDial | B5: Main Dial | C5: MC002 | D5: Turret | E5: L2 | F5: Active
A6: MC002-BarrierPreheatStation1 | B6: Barrier Preheat Station 1 | C6: MC002 | D6: Heating | E6: L2 | F6: Active
A7: MC002-BarrierPreheatStation2 | B7: Barrier Preheat Station 2 | C7: MC002 | D7: Heating | E7: L2 | F7: Active
A8: MC002-BarrierFormingStation | B8: Barrier Forming Station | C8: MC002 | D8: Forming | E8: L2 | F8: Active
A9: MC002-BarrierPunchStation | B9: Barrier Punch Station | C9: MC002 | D9: Punching | E9: L2 | F9: Active
A10: MC002-BarrierPrintStation | B10: Barrier Print Station | C10: MC002 | D10: Printing | E10: L2 | F10: Active
A11: MC002-BagInfeedConveyor | B11: Bag Infeed Conveyor | C11: MC002 | D11: Infeed | E11: L2 | F11: Active
A12: MC002-BagLoadRobot | B12: Bag Load Robot | C12: MC002 | D12: Robot/Pick-and-Place | E12: L2 | F12: Active
... A116: MC007-INS | B116: INS chain conveyor | C116: MC007 | D116: Feeding | E116: L2 | F116: Active

Sheet Parameters (Tags)
A1: ParameterID | B1: ParameterName | C1: StationID | D1: Unit_of_Measure | E1: Data_Type | F1: Min_Threshold | G1: Max_Threshold | H1: Target_Threshold | I1: Historian_Tag | J1: Hierarchy_Path
A2: PR0008 | B2: Barrier Infeed Elevator Counter | C2: MC002-BarrierInfeedSystem | E2: Integer | I2: BARRIER_INFEED_ELEVATOR | J2: =IFERROR(INDEX(Lines!$C$2:$C$1000,MATCH(INDEX(Machines!$C$2:$C$1000,MATCH(INDEX(Stations!$C$2:$C$1000,MATCH(C2,Stations!$A$2:$A$1000,0)),Machines!$A$2:$A$1000,0)),Lines!$A$2:$A$1000,0))&" / "&INDEX(Lines!$B$2:$B$1000,MATCH(INDEX(Machines!$C$2:$C$1000,MATCH(INDEX(Stations!$C$2:$C$1000,MATCH(C2,Stations!$A$2:$A$1000,0)),Machines!$A$2:$A$1000,0)),Lines!$A$2:$A$1000,0))&" / "&INDEX(Machines!$B$2:$B$1000,MATCH(INDEX(Stations!$C$2:$C$1000,MATCH(C2,Stations!$A$2:$A$1000,0)),Machines!$A$2:$A$1000,0))&" / "&INDEX(Stations!$B$2:$B$1000,MATCH(C2,Stations!$A$2:$A$1000,0))&" / "&B2,"check refs")
A3: PR0009 | B3: Corona Treat Position (Recipe) | C3: MC002-CoronaTreatment | E3: Float | I3: PNP_CORONA_POS_RECIPE | J3: =IFERROR(INDEX(Lines!$C$2:$C$1000,MATCH(INDEX(Machines!$C$2:$C$1000,MATCH(INDEX(Stations!$C$2:$C$1000,MATCH(C3,Stations!$A$2:$A$1000,0)),Machines!$A$2:$A$1000,0)),Lines!$A$2:$A$1000,0))&" / "&INDEX(Lines!$B$2:$B$1000,MATCH(INDEX(Machines!$C$2:$C$1000,MATCH(INDEX(Stations!$C$2:$C$1000,MATCH(C3,Stations!$A$2:$A$1000,0)),Machines!$A$2:$A$1000,0)),Lines!$A$2:$A$1000,0))&" / "&INDEX(Machines!$B$2:$B$1000,MATCH(INDEX(Stations!$C$2:$C$1000,MATCH(C3,Stations!$A$2:$A$1000,0)),Machines!$A$2:$A$1000,0))&" / "&INDEX(Stations!$B$2:$B$1000,MATCH(C3,Stations!$A$2:$A$1000,0))&" / "&B3,"check refs")
A4: PR0010 | B4: Main Dial Servo Drive Acceleration | C4: MC002-MainDial | E4: Float | I4: MAIN_DIAL_DRIVE_ACC_PB | J4: =IFERROR(INDEX(Lines!$C$2:$C$1000,MATCH(INDEX(Machines!$C$2:$C$1000,MATCH(INDEX(Stations!$C$2:$C$1000,MATCH(C4,Stations!$A$2:$A$1000,0)),Machines!$A$2:$A$1000,0)),Lines!$A$2:$A$1000,0))&" / "&INDEX(Lines!$B$2:$B$1000,MATCH(INDEX(Machines!$C$2:$C$1000,MATCH(INDEX(Stations!$C$2:$C$1000,MATCH(C4,Stations!$A$2:$A$1000,0)),Machines!$A$2:$A$1000,0)),Lines!$A$2:$A$1000,0))&" / "&INDEX(Machines!$B$2:$B$1000,MATCH(INDEX(Stations!$C$2:$C$1000,MATCH(C4,Stations!$A$2:$A$1000,0)),Machines!$A$2:$A$1000,0))&" / "&INDEX(Stations!$B$2:$B$1000,MATCH(C4,Stations!$A$2:$A$1000,0))&" / "&B4,"check refs")
A5: PR0011 | B5: Main Dial Servo Drive Deceleration | C5: MC002-MainDial | E5: Float | I5: MAIN_DIAL_DRIVE_DEC_PB | J5: =IFERROR(INDEX(Lines!$C$2:$C$1000,MATCH(INDEX(Machines!$C$2:$C$1000,MATCH(INDEX(Stations!$C$2:$C$1000,MATCH(C5,Stations!$A$2:$A$1000,0)),Machines!$A$2:$A$1000,0)),Lines!$A$2:$A$1000,0))&" / "&INDEX(Lines!$B$2:$B$1000,MATCH(INDEX(Machines!$C$2:$C$1000,MATCH(INDEX(Stations!$C$2:$C$1000,MATCH(C5,Stations!$A$2:$A$1000,0)),Machines!$A$2:$A$1000,0)),Lines!$A$2:$A$1000,0))&" / "&INDEX(Machines!$B$2:$B$1000,MATCH(INDEX(Stations!$C$2:$C$1000,MATCH(C5,Stations!$A$2:$A$1000,0)),Machines!$A$2:$A$1000,0))&" / "&INDEX(Stations!$B$2:$B$1000,MATCH(C5,Stations!$A$2:$A$1000,0))&" / "&B5,"check refs")
A6: PR0012 | B6: Main Dial Theoretical Registration Position | C6: MC002-MainDial | E6: Real | I6: MAIN_DIAL_REG_POSITION_THEO | J6: =IFERROR(INDEX(Lines!$C$2:$C$1000,MATCH(INDEX(Machines!$C$2:$C$1000,MATCH(INDEX(Stations!$C$2:$C$1000,MATCH(C6,Stations!$A$2:$A$1000,0)),Machines!$A$2:$A$1000,0)),Lines!$A$2:$A$1000,0))&" / "&INDEX(Lines!$B$2:$B$1000,MATCH(INDEX(Machines!$C$2:$C$1000,MATCH(INDEX(Stations!$C$2:$C$1000,MATCH(C6,Stations!$A$2:$A$1000,0)),Machines!$A$2:$A$1000,0)),Lines!$A$2:$A$1000,0))&" / "&INDEX(Machines!$B$2:$B$1000,MATCH(INDEX(Stations!$C$2:$C$1000,MATCH(C6,Stations!$A$2:$A$1000,0)),Machines!$A$2:$A$1000,0))&" / "&INDEX(Stations!$B$2:$B$1000,MATCH(C6,Stations!$A$2:$A$1000,0))&" / "&B6,"check refs")
A7: PR0013 | B7: Lower Tooling Offset Temperature Adjustment | C7: MC002-BarrierPreheatStation1 | D7: °C (unverified) | E7: Integer | I7: PREHEAT1_LOW_ADJ_TEMP | J7: =IFERROR(INDEX(Lines!$C$2:$C$1000,MATCH(INDEX(Machines!$C$2:$C$1000,MATCH(INDEX(Stations!$C$2:$C$1000,MATCH(C7,Stations!$A$2:$A$1000,0)),Machines!$A$2:$A$1000,0)),Lines!$A$2:$A$1000,0))&" / "&INDEX(Lines!$B$2:$B$1000,MATCH(INDEX(Machines!$C$2:$C$1000,MATCH(INDEX(Stations!$C$2:$C$1000,MATCH(C7,Stations!$A$2:$A$1000,0)),Machines!$A$2:$A$1000,0)),Lines!$A$2:$A$1000,0))&" / "&INDEX(Machines!$B$2:$B$1000,MATCH(INDEX(Stations!$C$2:$C$1000,MATCH(C7,Stations!$A$2:$A$1000,0)),Machines!$A$2:$A$1000,0))&" / "&INDEX(Stations!$B$2:$B$1000,MATCH(C7,Stations!$A$2:$A$1000,0))&" / "&B7,"check refs")
A8: PR0014 | B8: Lower Block Raw Temperature | C8: MC002-BarrierPreheatStation1 | E8: Integer | I8: PREHEAT1_LOW_BLOCK_TEMP | J8: =IFERROR(INDEX(Lines!$C$2:$C$1000,MATCH(INDEX(Machines!$C$2:$C$1000,MATCH(INDEX(Stations!$C$2:$C$1000,MATCH(C8,Stations!$A$2:$A$1000,0)),Machines!$A$2:$A$1000,0)),Lines!$A$2:$A$1000,0))&" / "&INDEX(Lines!$B$2:$B$1000,MATCH(INDEX(Machines!$C$2:$C$1000,MATCH(INDEX(Stations!$C$2:$C$1000,MATCH(C8,Stations!$A$2:$A$1000,0)),Machines!$A$2:$A$1000,0)),Lines!$A$2:$A$1000,0))&" / "&INDEX(Machines!$B$2:$B$1000,MATCH(INDEX(Stations!$C$2:$C$1000,MATCH(C8,Stations!$A$2:$A$1000,0)),Machines!$A$2:$A$1000,0))&" / "&INDEX(Stations!$B$2:$B$1000,MATCH(C8,Stations!$A$2:$A$1000,0))&" / "&B8,"check refs")
A9: PR0015 | B9: Lower Block Temperature (Display) | C9: MC002-BarrierPreheatStation1 | D9: °C (unverified) | E9: Float | I9: PREHEAT1_LOW_BLOCK_TEMP_DISPLAY | J9: =IFERROR(INDEX(Lines!$C$2:$C$1000,MATCH(INDEX(Machines!$C$2:$C$1000,MATCH(INDEX(Stations!$C$2:$C$1000,MATCH(C9,Stations!$A$2:$A$1000,0)),Machines!$A$2:$A$1000,0)),Lines!$A$2:$A$1000,0))&" / "&INDEX(Lines!$B$2:$B$1000,MATCH(INDEX(Machines!$C$2:$C$1000,MATCH(INDEX(Stations!$C$2:$C$1000,MATCH(C9,Stations!$A$2:$A$1000,0)),Machines!$A$2:$A$1000,0)),Lines!$A$2:$A$1000,0))&" / "&INDEX(Machines!$B$2:$B$1000,MATCH(INDEX(Stations!$C$2:$C$1000,MATCH(C9,Stations!$A$2:$A$1000,0)),Machines!$A$2:$A$1000,0))&" / "&INDEX(Stations!$B$2:$B$1000,MATCH(C9,Stations!$A$2:$A$1000,0))&" / "&B9,"check refs")
A10: PR0016 | B10: Lower Block Temperature (PID Input) | C10: MC002-BarrierPreheatStation1 | D10: °C (unverified) | E10: Float | I10: PREHEAT1_LOW_BLOCK_TEMP_REAL | J10: =IFERROR(INDEX(Lines!$C$2:$C$1000,MATCH(INDEX(Machines!$C$2:$C$1000,MATCH(INDEX(Stations!$C$2:$C$1000,MATCH(C10,Stations!$A$2:$A$1000,0)),Machines!$A$2:$A$1000,0)),Lines!$A$2:$A$1000,0))&" / "&INDEX(Lines!$B$2:$B$1000,MATCH(INDEX(Machines!$C$2:$C$1000,MATCH(INDEX(Stations!$C$2:$C$1000,MATCH(C10,Stations!$A$2:$A$1000,0)),Machines!$A$2:$A$1000,0)),Lines!$A$2:$A$1000,0))&" / "&INDEX(Machines!$B$2:$B$1000,MATCH(INDEX(Stations!$C$2:$C$1000,MATCH(C10,Stations!$A$2:$A$1000,0)),Machines!$A$2:$A$1000,0))&" / "&INDEX(Stations!$B$2:$B$1000,MATCH(C10,Stations!$A$2:$A$1000,0))&" / "&B10,"check refs")
A11: PR0019 | B11: Lower Tool Temperature Setpoint (Recipe) | C11: MC002-BarrierPreheatStation1 | D11: °C (unverified) | E11: Integer | F11: PREHEAT1_LOW_TEMP_MIN | G11: PREHEAT1_LOW_TEMP_MAX | I11: PREHEAT1_LOW_TEMP_RECIPE_SP | J11: =IFERROR(INDEX(Lines!$C$2:$C$1000,MATCH(INDEX(Machines!$C$2:$C$1000,MATCH(INDEX(Stations!$C$2:$C$1000,MATCH(C11,Stations!$A$2:$A$1000,0)),Machines!$A$2:$A$1000,0)),Lines!$A$2:$A$1000,0))&" / "&INDEX(Lines!$B$2:$B$1000,MATCH(INDEX(Machines!$C$2:$C$1000,MATCH(INDEX(Stations!$C$2:$C$1000,MATCH(C11,Stations!$A$2:$A$1000,0)),Machines!$A$2:$A$1000,0)),Lines!$A$2:$A$1000,0))&" / "&INDEX(Machines!$B$2:$B$1000,MATCH(INDEX(Stations!$C$2:$C$1000,MATCH(C11,Stations!$A$2:$A$1000,0)),Machines!$A$2:$A$1000,0))&" / "&INDEX(Stations!$B$2:$B$1000,MATCH(C11,Stations!$A$2:$A$1000,0))&" / "&B11,"check refs")
A12: PR0020 | B12: Lower Tooling Temperature Reject Count | C12: MC002-BarrierPreheatStation1 | E12: Integer | I12: PREHEAT1_LOW_TEMP_REJECT_CNT | J12: =IFERROR(INDEX(Lines!$C$2:$C$1000,MATCH(INDEX(Machines!$C$2:$C$1000,MATCH(INDEX(Stations!$C$2:$C$1000,MATCH(C12,Stations!$A$2:$A$1000,0)),Machines!$A$2:$A$1000,0)),Lines!$A$2:$A$1000,0))&" / "&INDEX(Lines!$B$2:$B$1000,MATCH(INDEX(Machines!$C$2:$C$1000,MATCH(INDEX(Stations!$C$2:$C$1000,MATCH(C12,Stations!$A$2:$A$1000,0)),Machines!$A$2:$A$1000,0)),Lines!$A$2:$A$1000,0))&" / "&INDEX(Machines!$B$2:$B$1000,MATCH(INDEX(Stations!$C$2:$C$1000,MATCH(C12,Stations!$A$2:$A$1000,0)),Machines!$A$2:$A$1000,0))&" / "&INDEX(Stations!$B$2:$B$1000,MATCH(C12,Stations!$A$2:$A$1000,0))&" / "&B12,"check refs")
A13: PR0021 | B13: Lower Tool Temperature Setpoint - Auto (PID) | C13: MC002-BarrierPreheatStation1 | D13: °C (unverified) | E13: Float | I13: PREHEAT1_LOW_TEMP_SP_AUTO | J13: =IFERROR(INDEX(Lines!$C$2:$C$1000,MATCH(INDEX(Machines!$C$2:$C$1000,MATCH(INDEX(Stations!$C$2:$C$1000,MATCH(C13,Stations!$A$2:$A$1000,0)),Machines!$A$2:$A$1000,0)),Lines!$A$2:$A$1000,0))&" / "&INDEX(Lines!$B$2:$B$1000,MATCH(INDEX(Machines!$C$2:$C$1000,MATCH(INDEX(Stations!$C$2:$C$1000,MATCH(C13,Stations!$A$2:$A$1000,0)),Machines!$A$2:$A$1000,0)),Lines!$A$2:$A$1000,0))&" / "&INDEX(Machines!$B$2:$B$1000,MATCH(INDEX(Stations!$C$2:$C$1000,MATCH(C13,Stations!$A$2:$A$1000,0)),Machines!$A$2:$A$1000,0))&" / "&INDEX(Stations!$B$2:$B$1000,MATCH(C13,Stations!$A$2:$A$1000,0))&" / "&B13,"check refs")
A14: PR0022 | B14: Lower Tool Temperature Setpoint - Auto (Display) | C14: MC002-BarrierPreheatStation1 | D14: °C (unverified) | E14: Integer | I14: PREHEAT1_LOW_TEMP_SP_AUTO_DISPLAY | J14: =IFERROR(INDEX(Lines!$C$2:$C$1000,MATCH(INDEX(Machines!$C$2:$C$1000,MATCH(INDEX(Stations!$C$2:$C$1000,MATCH(C14,Stations!$A$2:$A$1000,0)),Machines!$A$2:$A$1000,0)),Lines!$A$2:$A$1000,0))&" / "&INDEX(Lines!$B$2:$B$1000,MATCH(INDEX(Machines!$C$2:$C$1000,MATCH(INDEX(Stations!$C$2:$C$1000,MATCH(C14,Stations!$A$2:$A$1000,0)),Machines!$A$2:$A$1000,0)),Lines!$A$2:$A$1000,0))&" / "&INDEX(Machines!$B$2:$B$1000,MATCH(INDEX(Stations!$C$2:$C$1000,MATCH(C14,Stations!$A$2:$A$1000,0)),Machines!$A$2:$A$1000,0))&" / "&INDEX(Stations!$B$2:$B$1000,MATCH(C14,Stations!$A$2:$A$1000,0))&" / "&B14,"check refs")
A15: PR0023 | B15: Lower Tool Temperature Setpoint - Manual (PID) | C15: MC002-BarrierPreheatStation1 | D15: °C (unverified) | E15: Float | I15: PREHEAT1_LOW_TEMP_SP_MAN | J15: =IFERROR(INDEX(Lines!$C$2:$C$1000,MATCH(INDEX(Machines!$C$2:$C$1000,MATCH(INDEX(Stations!$C$2:$C$1000,MATCH(C15,Stations!$A$2:$A$1000,0)),Machines!$A$2:$A$1000,0)),Lines!$A$2:$A$1000,0))&" / "&INDEX(Lines!$B$2:$B$1000,MATCH(INDEX(Machines!$C$2:$C$1000,MATCH(INDEX(Stations!$C$2:$C$1000,MATCH(C15,Stations!$A$2:$A$1000,0)),Machines!$A$2:$A$1000,0)),Lines!$A$2:$A$1000,0))&" / "&INDEX(Machines!$B$2:$B$1000,MATCH(INDEX(Stations!$C$2:$C$1000,MATCH(C15,Stations!$A$2:$A$1000,0)),Machines!$A$2:$A$1000,0))&" / "&INDEX(Stations!$B$2:$B$1000,MATCH(C15,Stations!$A$2:$A$1000,0))&" / "&B15,"check refs")
A16: PR0024 | B16: Lower Tool Temperature Setpoint - Manual (Display) | C16: MC002-BarrierPreheatStation1 | D16: °C (unverified) | E16: Integer | I16: PREHEAT1_LOW_TEMP_SP_MAN_DISPLAY | J16: =IFERROR(INDEX(Lines!$C$2:$C$1000,MATCH(INDEX(Machines!$C$2:$C$1000,MATCH(INDEX(Stations!$C$2:$C$1000,MATCH(C16,Stations!$A$2:$A$1000,0)),Machines!$A$2:$A$1000,0)),Lines!$A$2:$A$1000,0))&" / "&INDEX(Lines!$B$2:$B$1000,MATCH(INDEX(Machines!$C$2:$C$1000,MATCH(INDEX(Stations!$C$2:$C$1000,MATCH(C16,Stations!$A$2:$A$1000,0)),Machines!$A$2:$A$1000,0)),Lines!$A$2:$A$1000,0))&" / "&INDEX(Machines!$B$2:$B$1000,MATCH(INDEX(Stations!$C$2:$C$1000,MATCH(C16,Stations!$A$2:$A$1000,0)),Machines!$A$2:$A$1000,0))&" / "&INDEX(Stations!$B$2:$B$1000,MATCH(C16,Stations!$A$2:$A$1000,0))&" / "&B16,"check refs")
A17: PR0025 | B17: Lower Tool Raw Temperature | C17: MC002-BarrierPreheatStation1 | E17: Integer | I17: PREHEAT1_LOW_TOOL_TEMP | J17: =IFERROR(INDEX(Lines!$C$2:$C$1000,MATCH(INDEX(Machines!$C$2:$C$1000,MATCH(INDEX(Stations!$C$2:$C$1000,MATCH(C17,Stations!$A$2:$A$1000,0)),Machines!$A$2:$A$1000,0)),Lines!$A$2:$A$1000,0))&" / "&INDEX(Lines!$B$2:$B$1000,MATCH(INDEX(Machines!$C$2:$C$1000,MATCH(INDEX(Stations!$C$2:$C$1000,MATCH(C17,Stations!$A$2:$A$1000,0)),Machines!$A$2:$A$1000,0)),Lines!$A$2:$A$1000,0))&" / "&INDEX(Machines!$B$2:$B$1000,MATCH(INDEX(Stations!$C$2:$C$1000,MATCH(C17,Stations!$A$2:$A$1000,0)),Machines!$A$2:$A$1000,0))&" / "&INDEX(Stations!$B$2:$B$1000,MATCH(C17,Stations!$A$2:$A$1000,0))&" / "&B17,"check refs")
A18: PR0026 | B18: Lower Tool Temperature (Display) | C18: MC002-BarrierPreheatStation1 | D18: °C (unverified) | E18: Float | I18: PREHEAT1_LOW_TOOL_TEMP_DISPLAY | J18: =IFERROR(INDEX(Lines!$C$2:$C$1000,MATCH(INDEX(Machines!$C$2:$C$1000,MATCH(INDEX(Stations!$C$2:$C$1000,MATCH(C18,Stations!$A$2:$A$1000,0)),Machines!$A$2:$A$1000,0)),Lines!$A$2:$A$1000,0))&" / "&INDEX(Lines!$B$2:$B$1000,MATCH(INDEX(Machines!$C$2:$C$1000,MATCH(INDEX(Stations!$C$2:$C$1000,MATCH(C18,Stations!$A$2:$A$1000,0)),Machines!$A$2:$A$1000,0)),Lines!$A$2:$A$1000,0))&" / "&INDEX(Machines!$B$2:$B$1000,MATCH(INDEX(Stations!$C$2:$C$1000,MATCH(C18,Stations!$A$2:$A$1000,0)),Machines!$A$2:$A$1000,0))&" / "&INDEX(Stations!$B$2:$B$1000,MATCH(C18,Stations!$A$2:$A$1000,0))&" / "&B18,"check refs")
A19: PR0027 | B19: Lower Tool Temperature (PID Input) | C19: MC002-BarrierPreheatStation1 | D19: °C (unverified) | E19: Float | I19: PREHEAT1_LOW_TOOL_TEMP_REAL | J19: =IFERROR(INDEX(Lines!$C$2:$C$1000,MATCH(INDEX(Machines!$C$2:$C$1000,MATCH(INDEX(Stations!$C$2:$C$1000,MATCH(C19,Stations!$A$2:$A$1000,0)),Machines!$A$2:$A$1000,0)),Lines!$A$2:$A$1000,0))&" / "&INDEX(Lines!$B$2:$B$1000,MATCH(INDEX(Machines!$C$2:$C$1000,MATCH(INDEX(Stations!$C$2:$C$1000,MATCH(C19,Stations!$A$2:$A$1000,0)),Machines!$A$2:$A$1000,0)),Lines!$A$2:$A$1000,0))&" / "&INDEX(Machines!$B$2:$B$1000,MATCH(INDEX(Stations!$C$2:$C$1000,MATCH(C19,Stations!$A$2:$A$1000,0)),Machines!$A$2:$A$1000,0))&" / "&INDEX(Stations!$B$2:$B$1000,MATCH(C19,Stations!$A$2:$A$1000,0))&" / "&B19,"check refs")
A20: PR0028 | B20: Preheat Time (Recipe) | C20: MC002-BarrierPreheatStation1 | D20: sec (unverified) | E20: Integer | I20: PREHEAT1_TIME_RECIPE | J20: =IFERROR(INDEX(Lines!$C$2:$C$1000,MATCH(INDEX(Machines!$C$2:$C$1000,MATCH(INDEX(Stations!$C$2:$C$1000,MATCH(C20,Stations!$A$2:$A$1000,0)),Machines!$A$2:$A$1000,0)),Lines!$A$2:$A$1000,0))&" / "&INDEX(Lines!$B$2:$B$1000,MATCH(INDEX(Machines!$C$2:$C$1000,MATCH(INDEX(Stations!$C$2:$C$1000,MATCH(C20,Stations!$A$2:$A$1000,0)),Machines!$A$2:$A$1000,0)),Lines!$A$2:$A$1000,0))&" / "&INDEX(Machines!$B$2:$B$1000,MATCH(INDEX(Stations!$C$2:$C$1000,MATCH(C20,Stations!$A$2:$A$1000,0)),Machines!$A$2:$A$1000,0))&" / "&INDEX(Stations!$B$2:$B$1000,MATCH(C20,Stations!$A$2:$A$1000,0))&" / "&B20,"check refs")
A21: PR0029 | B21: Upper Tooling Offset Temperature Adjustment | C21: MC002-BarrierPreheatStation1 | D21: °C (unverified) | E21: Integer | I21: PREHEAT1_UP_ADJ_TEMP | J21: =IFERROR(INDEX(Lines!$C$2:$C$1000,MATCH(INDEX(Machines!$C$2:$C$1000,MATCH(INDEX(Stations!$C$2:$C$1000,MATCH(C21,Stations!$A$2:$A$1000,0)),Machines!$A$2:$A$1000,0)),Lines!$A$2:$A$1000,0))&" / "&INDEX(Lines!$B$2:$B$1000,MATCH(INDEX(Machines!$C$2:$C$1000,MATCH(INDEX(Stations!$C$2:$C$1000,MATCH(C21,Stations!$A$2:$A$1000,0)),Machines!$A$2:$A$1000,0)),Lines!$A$2:$A$1000,0))&" / "&INDEX(Machines!$B$2:$B$1000,MATCH(INDEX(Stations!$C$2:$C$1000,MATCH(C21,Stations!$A$2:$A$1000,0)),Machines!$A$2:$A$1000,0))&" / "&INDEX(Stations!$B$2:$B$1000,MATCH(C21,Stations!$A$2:$A$1000,0))&" / "&B21,"check refs")
A22: PR0030 | B22: Upper Block Raw Temperature | C22: MC002-BarrierPreheatStation1 | E22: Integer | I22: PREHEAT1_UP_BLOCK_TEMP | J22: =IFERROR(INDEX(Lines!$C$2:$C$1000,MATCH(INDEX(Machines!$C$2:$C$1000,MATCH(INDEX(Stations!$C$2:$C$1000,MATCH(C22,Stations!$A$2:$A$1000,0)),Machines!$A$2:$A$1000,0)),Lines!$A$2:$A$1000,0))&" / "&INDEX(Lines!$B$2:$B$1000,MATCH(INDEX(Machines!$C$2:$C$1000,MATCH(INDEX(Stations!$C$2:$C$1000,MATCH(C22,Stations!$A$2:$A$1000,0)),Machines!$A$2:$A$1000,0)),Lines!$A$2:$A$1000,0))&" / "&INDEX(Machines!$B$2:$B$1000,MATCH(INDEX(Stations!$C$2:$C$1000,MATCH(C22,Stations!$A$2:$A$1000,0)),Machines!$A$2:$A$1000,0))&" / "&INDEX(Stations!$B$2:$B$1000,MATCH(C22,Stations!$A$2:$A$1000,0))&" / "&B22,"check refs")
A23: PR0031 | B23: Upper Block Temperature (Display) | C23: MC002-BarrierPreheatStation1 | D23: °C (unverified) | E23: Float | I23: PREHEAT1_UP_BLOCK_TEMP_DISPLAY | J23: =IFERROR(INDEX(Lines!$C$2:$C$1000,MATCH(INDEX(Machines!$C$2:$C$1000,MATCH(INDEX(Stations!$C$2:$C$1000,MATCH(C23,Stations!$A$2:$A$1000,0)),Machines!$A$2:$A$1000,0)),Lines!$A$2:$A$1000,0))&" / "&INDEX(Lines!$B$2:$B$1000,MATCH(INDEX(Machines!$C$2:$C$1000,MATCH(INDEX(Stations!$C$2:$C$1000,MATCH(C23,Stations!$A$2:$A$1000,0)),Machines!$A$2:$A$1000,0)),Lines!$A$2:$A$1000,0))&" / "&INDEX(Machines!$B$2:$B$1000,MATCH(INDEX(Stations!$C$2:$C$1000,MATCH(C23,Stations!$A$2:$A$1000,0)),Machines!$A$2:$A$1000,0))&" / "&INDEX(Stations!$B$2:$B$1000,MATCH(C23,Stations!$A$2:$A$1000,0))&" / "&B23,"check refs")
A24: PR0032 | B24: Upper Block Temperature (PID Input) | C24: MC002-BarrierPreheatStation1 | D24: °C (unverified) | E24: Float | I24: PREHEAT1_UP_BLOCK_TEMP_REAL | J24: =IFERROR(INDEX(Lines!$C$2:$C$1000,MATCH(INDEX(Machines!$C$2:$C$1000,MATCH(INDEX(Stations!$C$2:$C$1000,MATCH(C24,Stations!$A$2:$A$1000,0)),Machines!$A$2:$A$1000,0)),Lines!$A$2:$A$1000,0))&" / "&INDEX(Lines!$B$2:$B$1000,MATCH(INDEX(Machines!$C$2:$C$1000,MATCH(INDEX(Stations!$C$2:$C$1000,MATCH(C24,Stations!$A$2:$A$1000,0)),Machines!$A$2:$A$1000,0)),Lines!$A$2:$A$1000,0))&" / "&INDEX(Machines!$B$2:$B$1000,MATCH(INDEX(Stations!$C$2:$C$1000,MATCH(C24,Stations!$A$2:$A$1000,0)),Machines!$A$2:$A$1000,0))&" / "&INDEX(Stations!$B$2:$B$1000,MATCH(C24,Stations!$A$2:$A$1000,0))&" / "&B24,"check refs")
A25: PR0035 | B25: Upper Tool Temperature Setpoint (Recipe) | C25: MC002-BarrierPreheatStation1 | D25: °C (unverified) | E25: Integer | F25: PREHEAT1_UP_TEMP_MIN | G25: PREHEAT1_UP_TEMP_MAX | I25: PREHEAT1_UP_TEMP_RECIPE_SP | J25: =IFERROR(INDEX(Lines!$C$2:$C$1000,MATCH(INDEX(Machines!$C$2:$C$1000,MATCH(INDEX(Stations!$C$2:$C$1000,MATCH(C25,Stations!$A$2:$A$1000,0)),Machines!$A$2:$A$1000,0)),Lines!$A$2:$A$1000,0))&" / "&INDEX(Lines!$B$2:$B$1000,MATCH(INDEX(Machines!$C$2:$C$1000,MATCH(INDEX(Stations!$C$2:$C$1000,MATCH(C25,Stations!$A$2:$A$1000,0)),Machines!$A$2:$A$1000,0)),Lines!$A$2:$A$1000,0))&" / "&INDEX(Machines!$B$2:$B$1000,MATCH(INDEX(Stations!$C$2:$C$1000,MATCH(C25,Stations!$A$2:$A$1000,0)),Machines!$A$2:$A$1000,0))&" / "&INDEX(Stations!$B$2:$B$1000,MATCH(C25,Stations!$A$2:$A$1000,0))&" / "&B25,"check refs")
A26: PR0036 | B26: Upper Tooling Temperature Reject Count | C26: MC002-BarrierPreheatStation1 | E26: Integer | I26: PREHEAT1_UP_TEMP_REJECT_CNT | J26: =IFERROR(INDEX(Lines!$C$2:$C$1000,MATCH(INDEX(Machines!$C$2:$C$1000,MATCH(INDEX(Stations!$C$2:$C$1000,MATCH(C26,Stations!$A$2:$A$1000,0)),Machines!$A$2:$A$1000,0)),Lines!$A$2:$A$1000,0))&" / "&INDEX(Lines!$B$2:$B$1000,MATCH(INDEX(Machines!$C$2:$C$1000,MATCH(INDEX(Stations!$C$2:$C$1000,MATCH(C26,Stations!$A$2:$A$1000,0)),Machines!$A$2:$A$1000,0)),Lines!$A$2:$A$1000,0))&" / "&INDEX(Machines!$B$2:$B$1000,MATCH(INDEX(Stations!$C$2:$C$1000,MATCH(C26,Stations!$A$2:$A$1000,0)),Machines!$A$2:$A$1000,0))&" / "&INDEX(Stations!$B$2:$B$1000,MATCH(C26,Stations!$A$2:$A$1000,0))&" / "&B26,"check refs")
A27: PR0037 | B27: Upper Tool Temperature Setpoint - Auto (PID) | C27: MC002-BarrierPreheatStation1 | D27: °C (unverified) | E27: Float | I27: PREHEAT1_UP_TEMP_SP_AUTO | J27: =IFERROR(INDEX(Lines!$C$2:$C$1000,MATCH(INDEX(Machines!$C$2:$C$1000,MATCH(INDEX(Stations!$C$2:$C$1000,MATCH(C27,Stations!$A$2:$A$1000,0)),Machines!$A$2:$A$1000,0)),Lines!$A$2:$A$1000,0))&" / "&INDEX(Lines!$B$2:$B$1000,MATCH(INDEX(Machines!$C$2:$C$1000,MATCH(INDEX(Stations!$C$2:$C$1000,MATCH(C27,Stations!$A$2:$A$1000,0)),Machines!$A$2:$A$1000,0)),Lines!$A$2:$A$1000,0))&" / "&INDEX(Machines!$B$2:$B$1000,MATCH(INDEX(Stations!$C$2:$C$1000,MATCH(C27,Stations!$A$2:$A$1000,0)),Machines!$A$2:$A$1000,0))&" / "&INDEX(Stations!$B$2:$B$1000,MATCH(C27,Stations!$A$2:$A$1000,0))&" / "&B27,"check refs")
A28: PR0038 | B28: Upper Tool Temperature Setpoint - Auto (Display) | C28: MC002-BarrierPreheatStation1 | D28: °C (unverified) | E28: Integer | I28: PREHEAT1_UP_TEMP_SP_AUTO_DISPLAY | J28: =IFERROR(INDEX(Lines!$C$2:$C$1000,MATCH(INDEX(Machines!$C$2:$C$1000,MATCH(INDEX(Stations!$C$2:$C$1000,MATCH(C28,Stations!$A$2:$A$1000,0)),Machines!$A$2:$A$1000,0)),Lines!$A$2:$A$1000,0))&" / "&INDEX(Lines!$B$2:$B$1000,MATCH(INDEX(Machines!$C$2:$C$1000,MATCH(INDEX(Stations!$C$2:$C$1000,MATCH(C28,Stations!$A$2:$A$1000,0)),Machines!$A$2:$A$1000,0)),Lines!$A$2:$A$1000,0))&" / "&INDEX(Machines!$B$2:$B$1000,MATCH(INDEX(Stations!$C$2:$C$1000,MATCH(C28,Stations!$A$2:$A$1000,0)),Machines!$A$2:$A$1000,0))&" / "&INDEX(Stations!$B$2:$B$1000,MATCH(C28,Stations!$A$2:$A$1000,0))&" / "&B28,"check refs")
A29: PR0039 | B29: Upper Tool Temperature Setpoint - Manual (PID) | C29: MC002-BarrierPreheatStation1 | D29: °C (unverified) | E29: Float | I29: PREHEAT1_UP_TEMP_SP_MAN | J29: =IFERROR(INDEX(Lines!$C$2:$C$1000,MATCH(INDEX(Machines!$C$2:$C$1000,MATCH(INDEX(Stations!$C$2:$C$1000,MATCH(C29,Stations!$A$2:$A$1000,0)),Machines!$A$2:$A$1000,0)),Lines!$A$2:$A$1000,0))&" / "&INDEX(Lines!$B$2:$B$1000,MATCH(INDEX(Machines!$C$2:$C$1000,MATCH(INDEX(Stations!$C$2:$C$1000,MATCH(C29,Stations!$A$2:$A$1000,0)),Machines!$A$2:$A$1000,0)),Lines!$A$2:$A$1000,0))&" / "&INDEX(Machines!$B$2:$B$1000,MATCH(INDEX(Stations!$C$2:$C$1000,MATCH(C29,Stations!$A$2:$A$1000,0)),Machines!$A$2:$A$1000,0))&" / "&INDEX(Stations!$B$2:$B$1000,MATCH(C29,Stations!$A$2:$A$1000,0))&" / "&B29,"check refs")
A30: PR0040 | B30: Upper Tool Temperature Setpoint - Manual (Display) | C30: MC002-BarrierPreheatStation1 | D30: °C (unverified) | E30: Integer | I30: PREHEAT1_UP_TEMP_SP_MAN_DISPLAY | J30: =IFERROR(INDEX(Lines!$C$2:$C$1000,MATCH(INDEX(Machines!$C$2:$C$1000,MATCH(INDEX(Stations!$C$2:$C$1000,MATCH(C30,Stations!$A$2:$A$1000,0)),Machines!$A$2:$A$1000,0)),Lines!$A$2:$A$1000,0))&" / "&INDEX(Lines!$B$2:$B$1000,MATCH(INDEX(Machines!$C$2:$C$1000,MATCH(INDEX(Stations!$C$2:$C$1000,MATCH(C30,Stations!$A$2:$A$1000,0)),Machines!$A$2:$A$1000,0)),Lines!$A$2:$A$1000,0))&" / "&INDEX(Machines!$B$2:$B$1000,MATCH(INDEX(Stations!$C$2:$C$1000,MATCH(C30,Stations!$A$2:$A$1000,0)),Machines!$A$2:$A$1000,0))&" / "&INDEX(Stations!$B$2:$B$1000,MATCH(C30,Stations!$A$2:$A$1000,0))&" / "&B30,"check refs")
A31: PR0041 | B31: Upper Tool Raw Temperature | C31: MC002-BarrierPreheatStation1 | E31: Integer | I31: PREHEAT1_UP_TOOL_TEMP | J31: =IFERROR(INDEX(Lines!$C$2:$C$1000,MATCH(INDEX(Machines!$C$2:$C$1000,MATCH(INDEX(Stations!$C$2:$C$1000,MATCH(C31,Stations!$A$2:$A$1000,0)),Machines!$A$2:$A$1000,0)),Lines!$A$2:$A$1000,0))&" / "&INDEX(Lines!$B$2:$B$1000,MATCH(INDEX(Machines!$C$2:$C$1000,MATCH(INDEX(Stations!$C$2:$C$1000,MATCH(C31,Stations!$A$2:$A$1000,0)),Machines!$A$2:$A$1000,0)),Lines!$A$2:$A$1000,0))&" / "&INDEX(Machines!$B$2:$B$1000,MATCH(INDEX(Stations!$C$2:$C$1000,MATCH(C31,Stations!$A$2:$A$1000,0)),Machines!$A$2:$A$1000,0))&" / "&INDEX(Stations!$B$2:$B$1000,MATCH(C31,Stations!$A$2:$A$1000,0))&" / "&B31,"check refs")
A32: PR0042 | B32: Upper Tool Temperature (Display) | C32: MC002-BarrierPreheatStation1 | D32: °C (unverified) | E32: Float | I32: PREHEAT1_UP_TOOL_TEMP_DISPLAY | J32: =IFERROR(INDEX(Lines!$C$2:$C$1000,MATCH(INDEX(Machines!$C$2:$C$1000,MATCH(INDEX(Stations!$C$2:$C$1000,MATCH(C32,Stations!$A$2:$A$1000,0)),Machines!$A$2:$A$1000,0)),Lines!$A$2:$A$1000,0))&" / "&INDEX(Lines!$B$2:$B$1000,MATCH(INDEX(Machines!$C$2:$C$1000,MATCH(INDEX(Stations!$C$2:$C$1000,MATCH(C32,Stations!$A$2:$A$1000,0)),Machines!$A$2:$A$1000,0)),Lines!$A$2:$A$1000,0))&" / "&INDEX(Machines!$B$2:$B$1000,MATCH(INDEX(Stations!$C$2:$C$1000,MATCH(C32,Stations!$A$2:$A$1000,0)),Machines!$A$2:$A$1000,0))&" / "&INDEX(Stations!$B$2:$B$1000,MATCH(C32,Stations!$A$2:$A$1000,0))&" / "&B32,"check refs")
A33: PR0043 | B33: Upper Tool Temperature (PID Input) | C33: MC002-BarrierPreheatStation1 | D33: °C (unverified) | E33: Float | I33: PREHEAT1_UP_TOOL_TEMP_REAL | J33: =IFERROR(INDEX(Lines!$C$2:$C$1000,MATCH(INDEX(Machines!$C$2:$C$1000,MATCH(INDEX(Stations!$C$2:$C$1000,MATCH(C33,Stations!$A$2:$A$1000,0)),Machines!$A$2:$A$1000,0)),Lines!$A$2:$A$1000,0))&" / "&INDEX(Lines!$B$2:$B$1000,MATCH(INDEX(Machines!$C$2:$C$1000,MATCH(INDEX(Stations!$C$2:$C$1000,MATCH(C33,Stations!$A$2:$A$1000,0)),Machines!$A$2:$A$1000,0)),Lines!$A$2:$A$1000,0))&" / "&INDEX(Machines!$B$2:$B$1000,MATCH(INDEX(Stations!$C$2:$C$1000,MATCH(C33,Stations!$A$2:$A$1000,0)),Machines!$A$2:$A$1000,0))&" / "&INDEX(Stations!$B$2:$B$1000,MATCH(C33,Stations!$A$2:$A$1000,0))&" / "&B33,"check refs")
A34: PR0063 | B34: Lower Tooling Offset Temperature Adjustment | C34: MC002-BarrierPreheatStation2 | D34: °C (unverified) | E34: Integer | I34: PREHEAT2_LOW_ADJ_TEMP | J34: =IFERROR(INDEX(Lines!$C$2:$C$1000,MATCH(INDEX(Machines!$C$2:$C$1000,MATCH(INDEX(Stations!$C$2:$C$1000,MATCH(C34,Stations!$A$2:$A$1000,0)),Machines!$A$2:$A$1000,0)),Lines!$A$2:$A$1000,0))&" / "&INDEX(Lines!$B$2:$B$1000,MATCH(INDEX(Machines!$C$2:$C$1000,MATCH(INDEX(Stations!$C$2:$C$1000,MATCH(C34,Stations!$A$2:$A$1000,0)),Machines!$A$2:$A$1000,0)),Lines!$A$2:$A$1000,0))&" / "&INDEX(Machines!$B$2:$B$1000,MATCH(INDEX(Stations!$C$2:$C$1000,MATCH(C34,Stations!$A$2:$A$1000,0)),Machines!$A$2:$A$1000,0))&" / "&INDEX(Stations!$B$2:$B$1000,MATCH(C34,Stations!$A$2:$A$1000,0))&" / "&B34,"check refs")
A35: PR0064 | B35: Lower Block Raw Temperature | C35: MC002-BarrierPreheatStation2 | E35: Integer | I35: PREHEAT2_LOW_BLOCK_TEMP | J35: =IFERROR(INDEX(Lines!$C$2:$C$1000,MATCH(INDEX(Machines!$C$2:$C$1000,MATCH(INDEX(Stations!$C$2:$C$1000,MATCH(C35,Stations!$A$2:$A$1000,0)),Machines!$A$2:$A$1000,0)),Lines!$A$2:$A$1000,0))&" / "&INDEX(Lines!$B$2:$B$1000,MATCH(INDEX(Machines!$C$2:$C$1000,MATCH(INDEX(Stations!$C$2:$C$1000,MATCH(C35,Stations!$A$2:$A$1000,0)),Machines!$A$2:$A$1000,0)),Lines!$A$2:$A$1000,0))&" / "&INDEX(Machines!$B$2:$B$1000,MATCH(INDEX(Stations!$C$2:$C$1000,MATCH(C35,Stations!$A$2:$A$1000,0)),Machines!$A$2:$A$1000,0))&" / "&INDEX(Stations!$B$2:$B$1000,MATCH(C35,Stations!$A$2:$A$1000,0))&" / "&B35,"check refs")
A36: PR0065 | B36: Lower Block Temperature (Display) | C36: MC002-BarrierPreheatStation2 | D36: °C (unverified) | E36: Float | I36: PREHEAT2_LOW_BLOCK_TEMP_DISPLAY | J36: =IFERROR(INDEX(Lines!$C$2:$C$1000,MATCH(INDEX(Machines!$C$2:$C$1000,MATCH(INDEX(Stations!$C$2:$C$1000,MATCH(C36,Stations!$A$2:$A$1000,0)),Machines!$A$2:$A$1000,0)),Lines!$A$2:$A$1000,0))&" / "&INDEX(Lines!$B$2:$B$1000,MATCH(INDEX(Machines!$C$2:$C$1000,MATCH(INDEX(Stations!$C$2:$C$1000,MATCH(C36,Stations!$A$2:$A$1000,0)),Machines!$A$2:$A$1000,0)),Lines!$A$2:$A$1000,0))&" / "&INDEX(Machines!$B$2:$B$1000,MATCH(INDEX(Stations!$C$2:$C$1000,MATCH(C36,Stations!$A$2:$A$1000,0)),Machines!$A$2:$A$1000,0))&" / "&INDEX(Stations!$B$2:$B$1000,MATCH(C36,Stations!$A$2:$A$1000,0))&" / "&B36,"check refs")
A37: PR0066 | B37: Lower Block Temperature (PID Input) | C37: MC002-BarrierPreheatStation2 | D37: °C (unverified) | E37: Float | I37: PREHEAT2_LOW_BLOCK_TEMP_REAL | J37: =IFERROR(INDEX(Lines!$C$2:$C$1000,MATCH(INDEX(Machines!$C$2:$C$1000,MATCH(INDEX(Stations!$C$2:$C$1000,MATCH(C37,Stations!$A$2:$A$1000,0)),Machines!$A$2:$A$1000,0)),Lines!$A$2:$A$1000,0))&" / "&INDEX(Lines!$B$2:$B$1000,MATCH(INDEX(Machines!$C$2:$C$1000,MATCH(INDEX(Stations!$C$2:$C$1000,MATCH(C37,Stations!$A$2:$A$1000,0)),Machines!$A$2:$A$1000,0)),Lines!$A$2:$A$1000,0))&" / "&INDEX(Machines!$B$2:$B$1000,MATCH(INDEX(Stations!$C$2:$C$1000,MATCH(C37,Stations!$A$2:$A$1000,0)),Machines!$A$2:$A$1000,0))&" / "&INDEX(Stations!$B$2:$B$1000,MATCH(C37,Stations!$A$2:$A$1000,0))&" / "&B37,"check refs")
A38: PR0069 | B38: Lower Tool Temperature Setpoint (Recipe) | C38: MC002-BarrierPreheatStation2 | D38: °C (unverified) | E38: Integer | F38: PREHEAT2_LOW_TEMP_MIN | G38: PREHEAT2_LOW_TEMP_MAX | I38: PREHEAT2_LOW_TEMP_RECIPE_SP | J38: =IFERROR(INDEX(Lines!$C$2:$C$1000,MATCH(INDEX(Machines!$C$2:$C$1000,MATCH(INDEX(Stations!$C$2:$C$1000,MATCH(C38,Stations!$A$2:$A$1000,0)),Machines!$A$2:$A$1000,0)),Lines!$A$2:$A$1000,0))&" / "&INDEX(Lines!$B$2:$B$1000,MATCH(INDEX(Machines!$C$2:$C$1000,MATCH(INDEX(Stations!$C$2:$C$1000,MATCH(C38,Stations!$A$2:$A$1000,0)),Machines!$A$2:$A$1000,0)),Lines!$A$2:$A$1000,0))&" / "&INDEX(Machines!$B$2:$B$1000,MATCH(INDEX(Stations!$C$2:$C$1000,MATCH(C38,Stations!$A$2:$A$1000,0)),Machines!$A$2:$A$1000,0))&" / "&INDEX(Stations!$B$2:$B$1000,MATCH(C38,Stations!$A$2:$A$1000,0))&" / "&B38,"check refs")
A39: PR0070 | B39: Lower Tooling Temperature Reject Count | C39: MC002-BarrierPreheatStation2 | E39: Integer | I39: PREHEAT2_LOW_TEMP_REJECT_CNT | J39: =IFERROR(INDEX(Lines!$C$2:$C$1000,MATCH(INDEX(Machines!$C$2:$C$1000,MATCH(INDEX(Stations!$C$2:$C$1000,MATCH(C39,Stations!$A$2:$A$1000,0)),Machines!$A$2:$A$1000,0)),Lines!$A$2:$A$1000,0))&" / "&INDEX(Lines!$B$2:$B$1000,MATCH(INDEX(Machines!$C$2:$C$1000,MATCH(INDEX(Stations!$C$2:$C$1000,MATCH(C39,Stations!$A$2:$A$1000,0)),Machines!$A$2:$A$1000,0)),Lines!$A$2:$A$1000,0))&" / "&INDEX(Machines!$B$2:$B$1000,MATCH(INDEX(Stations!$C$2:$C$1000,MATCH(C39,Stations!$A$2:$A$1000,0)),Machines!$A$2:$A$1000,0))&" / "&INDEX(Stations!$B$2:$B$1000,MATCH(C39,Stations!$A$2:$A$1000,0))&" / "&B39,"check refs")
A40: PR0071 | B40: Lower Tool Temperature Setpoint - Auto (PID) | C40: MC002-BarrierPreheatStation2 | D40: °C (unverified) | E40: Float | I40: PREHEAT2_LOW_TEMP_SP_AUTO | J40: =IFERROR(INDEX(Lines!$C$2:$C$1000,MATCH(INDEX(Machines!$C$2:$C$1000,MATCH(INDEX(Stations!$C$2:$C$1000,MATCH(C40,Stations!$A$2:$A$1000,0)),Machines!$A$2:$A$1000,0)),Lines!$A$2:$A$1000,0))&" / "&INDEX(Lines!$B$2:$B$1000,MATCH(INDEX(Machines!$C$2:$C$1000,MATCH(INDEX(Stations!$C$2:$C$1000,MATCH(C40,Stations!$A$2:$A$1000,0)),Machines!$A$2:$A$1000,0)),Lines!$A$2:$A$1000,0))&" / "&INDEX(Machines!$B$2:$B$1000,MATCH(INDEX(Stations!$C$2:$C$1000,MATCH(C40,Stations!$A$2:$A$1000,0)),Machines!$A$2:$A$1000,0))&" / "&INDEX(Stations!$B$2:$B$1000,MATCH(C40,Stations!$A$2:$A$1000,0))&" / "&B40,"check refs")
...
